Workbook

Sheet README
A1: Robotic arm: CAD-based kinematics workbook
A2: Source: Fusion file ARM_ASSEMBLY (project 6-DOF-Robotic-Arm-Original). Updated 28 Oct 2026. This workbook is an offline geometry/reference aid only: it does not command hardware and its numbers are not validated motion commands. CAD joints were temporarily posed for validation and restored to their original values; geometry was not changed.
A4: QUICK START FOR FK / IK
A5: 1. Inputs: confirm the yellow cells (servo signs, foot height, TCP). The signs are a candidate model mapping and must be retested on the real arm (Servo_Map explains the small 1° physical check).
A6: 2. FK_Calculator: type servo angles → tool point X, Y, Z (mm) and orientation.
A7: 3. IK_Calculator: type a target X, Y, Z and the gripper pitch φ → servo angles (roll fixed at the reference).
A8: 4. Test_Vectors: 9 FK cases and 4 IK cases typed from the CAD, to unit-test your own code. These are typed CAD values, not hardware proof.
A10: SHEETS
A11: Inputs · Model_Params (all numbers the equations use, pulled by formula) · Servo_Map · FK_Calculator · IK_Calculator · Test_Vectors · J1_Location (where J1 is on the base plate) · Joint_Axes (all joint axes, CAD and robot frame) · Link_Lengths · Object_Check · Open_Items
A13: COORDINATE FRAMES
A14: Robot frame: origin = J1 axis on the floor/support plane under the base plate; +X forward (towards the curved side of base_link); +Y robot's left; +Z up.
A15: Fusion frame: Y up. Robot X = −Fusion X; robot Y = Fusion Z − 18.18; robot Z = Fusion Y + 34.5 (+ foot height). This mapping is right-handed (checked).
... A27: Blue text = typed values (CAD readings or our measurements). Black = formulas. Green = linked from another sheet. Yellow fill = cells you edit or must confirm.

Sheet Inputs
A1: Inputs & reference values
A3: Parameter | B3: Value | C3: Unit | D3: Source / note
A4: Black arrow (robot +X) points toward | B4: -Fusion X | D4: CONFIRMED: you said the front is the curved side of base_link. CAD: that curved r=49 mm wall spans Fusion X −49…0 and the flat box is on +X, so forward = Fusion −X.
A5: Sign s (auto) | B5: =IF(B4="+Fusion X",1,IF(B4="-Fusion X",-1,"")) | D5: Formula – do not edit
A6: Foot / pad height under real plate | B6: 0 | C6: mm | D6: FILL IN: 0 if the plate sits flat on the table. CAD has no feet.
A7: J1 axis Fusion X | B7: 0 | C7: mm | D7: CAD: Revolute Base joint origin / servo spline / bearing bore centre
A8: J1 axis Fusion Z | B8: 18.18 | C8: mm | D8: CAD: same features, all concentric
A9: Plate bottom face Fusion Y | B9: -34.5 | C9: mm | D9: CAD: base_plate bottom face
A10: Plate top face Fusion Y | B10: -30.5 | C10: mm | D10: CAD: base_plate top face
A12: Servo reference angle J1 (= model 0) | B12: 85 | C12: deg | D12: User-supplied candidate zero on the real arm; zero alignment is provisional (see Servo_Map).
A13: Servo reference angle J2 (= model 0) | B13: 145 | C13: deg | D13: User-supplied candidate zero on the real arm; zero alignment is provisional (see Servo_Map).
A14: Servo reference angle J3 (= model 0) | B14: 88 | C14: deg | D14: User-supplied candidate zero on the real arm; zero alignment is provisional (see Servo_Map).
A15: Servo reference angle J4 (= model 0) | B15: 88 | C15: deg | D15: User-supplied candidate zero on the real arm; zero alignment is provisional (see Servo_Map).
A16: Servo reference angle J5 (= model 0) | B16: 96 | C16: deg | D16: User-supplied candidate zero on the real arm; zero alignment is provisional (see Servo_Map).
A17: J6 gripper closed | B17: 0 | C17: deg | D17: Our team
A18: J6 gripper startup / home | B18: 40 | C18: deg | D18: Our team. Startup/home only; not the holding angle (holding = 20°).
A19: J6 angle while holding the object | B19: 20 | C19: deg | D19: Known measured holding angle = 20°. This is not the 40° startup/home angle and not the separate CAD gear angle (also 20°); CAD gear geometry is not a holding measurement.
A21: Tool point (TCP) in the reference pose, robot frame
A22: TCP X at reference pose | B22: 10.15 | C22: mm | D22: Reference TCP is CAD-derived/imposed, not an independently measured CAD block centre. CAD jaw-gap centreline gives 10.10 (see Object_Check).
A23: TCP Y at reference pose | B23: 9.52 | C23: mm | D23: Offline hybrid model; the reference is CAD-derived/imposed, not independently measured. CAD jaw-gap centreline gives 9.37.
A24: TCP Z at reference pose | B24: 438.5 | C24: mm | D24: Derived: measured block top 446 mm − 15/2 (assumes 15 mm vertical and a level top). Used to construct the tool offset, so the reference height matches by construction, not independently.
A26: Servo direction signs (candidate model mapping; retest on the real arm – not CAD axis signs)
A27: Sign J1 | B27: 1 | C27: ±1 | D27: +1 if increasing the servo angle moves the joint in the model's + direction (defined on Servo_Map); −1 if opposite.
A28: Sign J2 | B28: -1 | C28: ±1 | D28: +1 if increasing the servo angle moves the joint in the model's + direction (defined on Servo_Map); −1 if opposite.
A29: Sign J3 | B29: 1 | C29: ±1 | D29: +1 if increasing the servo angle moves the joint in the model's + direction (defined on Servo_Map); −1 if opposite.
A30: Sign J4 | B30: 1 | C30: ±1 | D30: +1 if increasing the servo angle moves the joint in the model's + direction (defined on Servo_Map); −1 if opposite.
A31: Sign J5 | B31: -1 | C31: ±1 | D31: Provisional: J5 sign still needs retesting at the active J4 = 88°.
A32: Sign validation | B32: =IF(AND(COUNT(B27:B31)=5,SUMPRODUCT(--(ABS(B27:B31)<>1))=0),"OK: signs are ±1","INVALID: each sign must be exactly +1 or -1") | C32: ±1 | D32: Formula check only: signed model mapping, not CAD axis signs. Values outside ±1 make FK/IK inputs invalid.
A33: Installed servo endpoints (candidate per joint – endpoint check only, not collision-safe)
A34: Joint | B34: Min (deg) | C34: Max (deg) | D34: Note
A35: J1 | B35: 0 | C35: 180 | D35: Base yaw
A36: J2 | B36: 50 | C36: 180 | D36: Shoulder
A37: J3 | B37: 45 | C37: 180 | D37: Elbow
A38: J4 | B38: 0 | C38: 180 | D38: Wrist roll
A39: J5 | B39: 25 | C39: 140 | D39: Wrist pitch
A40: J6 | B40: 0 | C40: 60 | D40: Gripper; 40 = startup/home only
A41: Endpoints are candidate software limits / finite sample bounds, not a certified-safe workspace. Firmware motion retains commanded-state and pending-endpoint interlocks; physical path clearance still needs verification, and there is no automated collision guarantee.

Sheet Model_Params
A1: Model parameters (robot frame, zero pose = CAD as-built pose = servo reference pose)
A2: Everything here is a formula pulling from Joint_Axes and Inputs, so it updates if the arrow, foot height or TCP change. FK_Calculator, IK_Calculator and Test_Vectors all read this sheet. Zero pose: arm straight up, all q = 0.
A4: Quantity | B4: X (mm) | C4: Y (mm) | D4: Z (mm) | E4: Meaning
A5: S shoulder (J2) axis point | B5: =Joint_Axes!L6 | C5: =Joint_Axes!M8 | D5: =Joint_Axes!N6 | E5: A point on the J2 axis. In this model J2/J3/J5 pitch axes are parallel to robot Y (J4 roll is not); the Y coordinate is arbitrary and the arm-plane Y is used. D5 is fixed by the base/foot height, not by arm joint angles.
A6: E elbow (J3) axis point | B6: =Joint_Axes!L7 | C6: =Joint_Axes!M8 | D6: =Joint_Axes!N7 | E6: A point on the J3 axis.
A7: W wrist centre (J4 roll axis ∩ J5 pitch axis) | B7: =Joint_Axes!L9 | C7: =Joint_Axes!M8 | D7: =Joint_Axes!N9 | E7: The J4 and J5 axes intersect here (checked in CAD).
A8: TCP at reference pose (block centre) | B8: =Inputs!B22 | C8: =Inputs!B23 | D8: =Inputs!B24 | E8: Tool point used by FK/IK. Edit on Inputs. The reference is CAD-derived/imposed, not an independently measured CAD block centre.
A9: v_SE = E − S | B9: =B6-B5 | C9: =C6-C5 | D9: =D6-D5 | E9: Upper-arm vector at zero pose
A10: v_EW = W − E | B10: =B7-B6 | C10: =C7-C6 | D10: =D7-D6 | E10: Forearm vector at zero pose
A11: t = TCP − W (tool offset in zero pose) | B11: =B8-B7 | C11: =C8-C7 | D11: =D8-D7 | E11: Gripper offset from the wrist centre. Note X/Y are non-zero: the gripper's grip centre is NOT on the roll axis.
A13: Derived | B13: Value | E13: Meaning
A14: L2 upper-arm length (mm) | B14: =SQRT(B9^2+D9^2) | E14: |v_SE|
A15: L3 forearm length (mm) | B15: =SQRT(B10^2+D10^2) | E15: |v_EW|
A16: δ upper-arm lean at zero (rad) | B16: =ATAN2(D9,B9) | E16: ~0: the CAD has a 0.01 mm sideways offset between shoulder and elbow axes; included for exactness.
A17: d arm-plane offset from J1 axis, robot Y (mm) | B17: =C7 | E17: Constant sideways offset of the shoulder/elbow/wrist plane from the J1 axis
A19: Model equations (q in radians; Ry, Rz are right-handed rotations about robot Y and Z)
A20: TCP = Rz(q1) · [ S + Ry(q2)·v_SE + Ry(q2+q3)·( v_EW + Rz(q4)·Ry(q5)·t ) ]
A21: Gripper orientation R = Rz(q1) · Ry(q2+q3) · Rz(q4) · Ry(q5) (approach = R·ẑ, jaw-opening axis = R·ŷ)
A22: Model angle q = sign × (servo − servo_reference). Zero pose (all q=0) = servo 85 / 145 / 88 / 88 / 96.
A23: Validated against the Fusion model: 9 poses incl. combined moves, max difference 0.01512 mm (typed CAD values read to 0.01 mm; see Test_Vectors).

Sheet Servo_Map
A1: Servo ↔ model angle mapping
A2: q = sign × (servo − reference). Candidate zeros are 85 / 145 / 88 / 88 / 96. The signs are the signed model mapping, not CAD axis signs: J1 = +1, J2 = −1, J3 = +1, J4 = +1, J5 = −1 (J5 is provisional at the active J4 = 88°). Retest on the real arm and enter on Inputs!B27:B31.
A4: Joint | B4: Servo reference (deg) | C4: Sign (Inputs) | D4: Meaning of + q (model) | E4: Fusion joint name | F4: Fusion joint value = f × q | G4: Servo (input, deg) | H4: q from servo (deg) | I4: q (input, deg) | J4: Servo from q (deg)
A5: J1 base yaw | B5: =Inputs!B12 | C5: =Inputs!B27 | D5: Counter-clockwise seen from above (turns the arm toward +Y, the robot's left) | E5: Revolute Base | F5: -1 | G5: =B5 | H5: =C5*(G5-B5) | I5: 0 | J5: =B5+C5*I5
A6: J2 shoulder | B6: =Inputs!B13 | C6: =Inputs!B28 | D6: Upper arm tilts FORWARD (+X) from vertical | E6: Revolute Shoulder | F6: -1 | G6: =B6 | H6: =C6*(G6-B6) | I6: 0 | J6: =B6+C6*I6
A7: J3 elbow | B7: =Inputs!B14 | C7: =Inputs!B29 | D7: Forearm bends FORWARD (+X) relative to the upper arm | E7: Revolute Elbow | F7: 1 | G7: =B7 | H7: =C7*(G7-B7) | I7: 0 | J7: =B7+C7*I7
A8: J4 wrist roll | B8: =Inputs!B15 | C8: =Inputs!B30 | D8: Right-hand rotation about the forearm axis (elbow→gripper): counter-clockwise seen from above when the arm is vertical | E8: Revolute Wrist Roll | F8: -1 | G8: =B8 | H8: =C8*(G8-B8) | I8: 0 | J8: =B8+C8*I8
A9: J5 wrist pitch | B9: =Inputs!B16 | C9: =Inputs!B31 | D9: Gripper tilts FORWARD (+X) relative to the forearm | E9: Revolute Wrist Pitch | F9: -1 | G9: =B9 | H9: =C9*(G9-B9) | I9: 0 | J9: =B9+C9*I9
A11: J6 gripper
A12: Closed = 0°, startup/home = 40° (home only). Holding angle = 20° (Inputs!B19). The CAD gears are also at 20°, but that is separate CAD jaw geometry, not the holding measurement; the CAD jaw-pad gap ≈27.9 mm at the tips is not a seated block.
A14: How to find each servo's sign on the real arm (1° physical check)
A15: 1. Move the arm to the candidate reference pose (servos 85/145/88/88/96) with the arm clear; do not force any joint.
A16: 2. Command ONE servo to reference + 1° or −1° as a small, slow physical move (use the calibration tool/firmware; this workbook does not command hardware). Watch which way that joint moves.
A17: 3. Compare with 'Meaning of + q' above. Same direction → +1; opposite → −1. Enter in Inputs!B27:B31, return to the reference, repeat. J5 is provisional: recheck at J4 = 88°.
A18: 4. Do not use IK values to test signs or command the arm. Recheck with a separate multipose physical measurement before trusting the zero and signs.
A20: Zero-pose alignment (provisional – not validated by the height match)
A21: • The candidate zero 85/145/88/88/96 is user-supplied. Alignment of the real arm to the CAD as-built pose is not independently verified.
A22: • The measured 438.5 mm block-centre Z was used to construct the tool offset; the reference height therefore matches by construction, not by independent validation.
A23: • CAD jaw-pad heights and the jaw-gap centreline describe CAD jaw geometry only. They are not a seated block centre and do not prove the real arm is vertical.
A24: • Needs a multipose physical check: measure the tool position at several servo poses and compare with FK before calling the zero aligned.

Sheet FK_Calculator
A1: Forward kinematics: servo angles → tool point (robot frame)
A2: Type the five servo angles in the yellow cells. Output is the block-centre/tool point in mm in the robot frame (origin = J1 axis on the floor, +X forward, +Y left, +Z up). Default inputs = the reference pose. Signs are the candidate model mapping; the validation row flags bad signs. The endpoint check uses the per-joint table on Inputs, not a generic 0–180° range.
A4: Joint | B4: Servo angle (deg) | C4: q (deg) | D4: q (rad) | E4: Servo range check
A5: J1 base yaw | B5: 85 | C5: =Inputs!B27*(B5-Inputs!B12) | D5: =RADIANS(C5) | E5: =IF(AND(B5>=Inputs!$B$35,B5<=Inputs!$C$35),"OK","OUT OF RANGE")
A6: J2 shoulder | B6: 145 | C6: =Inputs!B28*(B6-Inputs!B13) | D6: =RADIANS(C6) | E6: =IF(AND(B6>=Inputs!$B$36,B6<=Inputs!$C$36),"OK","OUT OF RANGE")
A7: J3 elbow | B7: 88 | C7: =Inputs!B29*(B7-Inputs!B14) | D7: =RADIANS(C7) | E7: =IF(AND(B7>=Inputs!$B$37,B7<=Inputs!$C$37),"OK","OUT OF RANGE")
A8: J4 wrist roll | B8: 88 | C8: =Inputs!B30*(B8-Inputs!B15) | D8: =RADIANS(C8) | E8: =IF(AND(B8>=Inputs!$B$38,B8<=Inputs!$C$38),"OK","OUT OF RANGE")
A9: J5 wrist pitch | B9: 96 | C9: =Inputs!B31*(B9-Inputs!B16) | D9: =RADIANS(C9) | E9: =IF(AND(B9>=Inputs!$B$39,B9<=Inputs!$C$39),"OK","OUT OF RANGE")
A10: Sign validation | B10: =IF(Inputs!$B$32="OK: signs are ±1","OK","INVALID: check Inputs!B27:B31") | D10: Endpoint summary | E10: =IF(Inputs!$B$32<>"OK: signs are ±1","INVALID SIGNS; ","")&IF(COUNTIF(E5:E9,"OK")<5,"OUT OF RANGE ("&COUNTIF(E5:E9,"OK")&"/5); ","RANGES OK; ")&"J2/J5 coupling "&IF(AND(B6<90,B9<65),"VIOLATED","OK")
A11: Result
A12: Point | B12: X (mm) | C12: Y (mm) | D12: Z (mm)
A13: Tool point (TCP) | B13: =B33 | C13: =C33 | D13: =D33
A14: Wrist centre W | B14: =COS($D$5)*B37-SIN($D$5)*C37 | C14: =SIN($D$5)*B37+COS($D$5)*C37 | D14: =D37
A15: Elbow axis point E | B15: =COS($D$5)*B38-SIN($D$5)*C38 | C15: =SIN($D$5)*B38+COS($D$5)*C38 | D15: =D38
A16: Shoulder axis point S | B16: =COS($D$5)*Model_Params!B5-SIN($D$5)*Model_Params!C5 | C16: =SIN($D$5)*Model_Params!B5+COS($D$5)*Model_Params!C5 | D16: =Model_Params!D5
A18: Orientation | B18: X | C18: Y | D18: Z
A19: Approach direction (tool +Z: where the jaws point) | B19: =COS($D$5)*B42-SIN($D$5)*C42 | C19: =SIN($D$5)*B42+COS($D$5)*C42 | D19: =D42
A20: Jaw-opening axis (tool +Y: across the 25 mm width) | B20: =COS($D$5)*B44-SIN($D$5)*C44 | C20: =SIN($D$5)*B44+COS($D$5)*C44 | D20: =D44
A21: Planar tool pitch φ = q2+q3+q5 (deg; valid only when q4 = 0) | B21: =IF(ABS(C8)<0.000000001,C6+C7+C9,"Planar only: q4 must be 0")
A25: Calculation steps (all in mm / rad)
A26: u = Ry(q5)·t | B26: =Model_Params!$B$11*COS($D$9)+Model_Params!$D$11*SIN($D$9) | C26: =Model_Params!$C$11 | D26: =-Model_Params!$B$11*SIN($D$9)+Model_Params!$D$11*COS($D$9)
A27: v = Rz(q4)·u | B27: =COS($D$8)*B26-SIN($D$8)*C26 | C27: =SIN($D$8)*B26+COS($D$8)*C26 | D27: =D26
A28: w = v_EW + v | B28: =Model_Params!$B$10+B27 | C28: =Model_Params!$C$10+C27 | D28: =Model_Params!$D$10+D27
A29: q2+q3 (rad) | B29: =$D$6+$D$7
A30: Ry(q2+q3)·w | B30: =B28*COS(B29)+D28*SIN(B29) | C30: =C28 | D30: =-B28*SIN(B29)+D28*COS(B29)
A31: Ry(q2)·v_SE | B31: =Model_Params!$B$9*COS($D$6)+Model_Params!$D$9*SIN($D$6) | C31: =Model_Params!$C$9 | D31: =-Model_Params!$B$9*SIN($D$6)+Model_Params!$D$9*COS($D$6)
A32: p' = Ry(q23)·w + Ry(q2)·v_SE + S (arm plane) | B32: =B30+B31+Model_Params!$B$5 | C32: =C30+C31+Model_Params!$C$5 | D32: =D30+D31+Model_Params!$D$5
A33: TCP = Rz(q1)·p' | B33: =COS($D$5)*B32-SIN($D$5)*C32 | C33: =SIN($D$5)*B32+COS($D$5)*C32 | D33: =D32
A35: Wrist-centre & elbow helpers (arm plane)
A36: Ry(q23)·v_EW | B36: =Model_Params!$B$10*COS(B29)+Model_Params!$D$10*SIN(B29) | C36: =Model_Params!$C$10 | D36: =-Model_Params!$B$10*SIN(B29)+Model_Params!$D$10*COS(B29)
A37: W' = Ry(q23)·v_EW + Ry(q2)·v_SE + S | B37: =B36+B31+Model_Params!$B$5 | C37: =C36+C31+Model_Params!$C$5 | D37: =D36+D31+Model_Params!$D$5
A38: E' = Ry(q2)·v_SE + S | B38: =B31+Model_Params!$B$5 | C38: =C31+Model_Params!$C$5 | D38: =D31+Model_Params!$D$5
A40: Orientation steps
A41: a0 = Rz(q4)·Ry(q5)·ẑ | B41: =COS($D$8)*SIN($D$9) | C41: =SIN($D$8)*SIN($D$9) | D41: =COS($D$9)
A42: a1 = Ry(q23)·a0 | B42: =B41*COS(B29)+D41*SIN(B29) | C42: =C41 | D42: =-B41*SIN(B29)+D41*COS(B29)
A43: b0 = Rz(q4)·ŷ | B43: =-SIN($D$8) | C43: =COS($D$8) | D43: =0
A44: b1 = Ry(q23)·b0 | B44: =B43*COS(B29)+D43*SIN(B29) | C44: =C43 | D44: =-B43*SIN(B29)+D43*COS(B29)

Sheet IK_Calculator
A1: Inverse kinematics: target tool point → servo angles (closed form, roll q4 = 0)
A2: Enter the tool target in the robot frame and how the gripper should point. φ is the gripper's approach angle in the vertical arm plane: 0° = up, 90° = forward (+X), 180° = down. The ±1 switch picks the elbow solution. Roll is fixed at the reference (q4 = 0). The in-plane radial coordinate uses the positive square root only (x' ≥ 0); other radial/roll solutions are not enumerated. Defaults = a geometry example; with the current candidate signs the J2 endpoint is outside its installed range, and the endpoint check flags that without changing the target.
A4: Input | B4: Value | C4: Unit | D4: Note
A5: Target X | B5: 120 | C5: mm | D5: Robot frame, forward
A6: Target Y | B6: 20 | C6: mm | D6: Robot frame, left
A7: Target Z | B7: 300 | C7: mm | D7: Height above the floor / support plane
A8: Approach pitch φ | B8: 90 | C8: deg | D8: 0 = up, 90 = forward, 180 = straight down
A9: Elbow branch (must be exactly +1 or −1) | B9: 1 | D9: +1: q3 ≥ 0 (forearm bent forward); −1: q3 ≤ 0. Branch signs only; the 0.01 mm shoulder lean makes the q3 = 0 split approximate, not exact.
A11: Reachability status (geometry only) | B11: =IF(NOT(AND(ISNUMBER(B9),OR(B9=1,B9=-1))),"INVALID INPUT: elbow branch must be +1 or -1",IF(Inputs!$B$32<>"OK: signs are ±1","INVALID INPUT: servo signs on Inputs must be exactly +1 or -1",IF(B26<ABS(B25),"OUT OF REACH: too close to the J1 axis",IF(ABS(B30)>1,"OUT OF REACH: arm cannot span target","REACHABLE (geometry only)"))))
A12: Endpoint check (servo ranges + J2/J5 coupling) | B12: =IF($B$11<>"REACHABLE (geometry only)","not evaluated: IK is not reachable",IF(COUNTIF($D$14:$D$18,"OK")<5,"OUTSIDE installed servo endpoints ("&COUNTIF($D$14:$D$18,"OK")&"/5 within range); J2/J5 coupling "&IF(AND($C$15<90,$C$18<65),"VIOLATED","OK"),"Within installed servo endpoints; J2/J5 coupling "&IF(AND($C$15<90,$C$18<65),"VIOLATED","OK"))) | D12: Endpoint check only: installed servo ranges plus J2<90 requires J5≥65 (equivalently J5<65 requires J2≥90; boundaries inclusive). Not a certified-safe workspace or automated collision check. Firmware motion retains commanded-state and pending-endpoint interlocks; physical path clearance still needs verification, and there is no automated collision guarantee.
A13: Result | B13: q (deg) | C13: Servo angle (deg) | D13: Servo range check
A14: J1 base yaw | B14: =IF($B$11<>"REACHABLE (geometry only)","",DEGREES(B33)) | C14: =IF($B$11<>"REACHABLE (geometry only)","",Inputs!B12+Inputs!B27*B14) | D14: =IF($B$11<>"REACHABLE (geometry only)","",IF(AND(C14>=Inputs!$B$35,C14<=Inputs!$C$35),"OK","OUT OF RANGE"))
A15: J2 shoulder | B15: =IF($B$11<>"REACHABLE (geometry only)","",DEGREES(B34)) | C15: =IF($B$11<>"REACHABLE (geometry only)","",Inputs!B13+Inputs!B28*B15) | D15: =IF($B$11<>"REACHABLE (geometry only)","",IF(AND(C15>=Inputs!$B$36,C15<=Inputs!$C$36),"OK","OUT OF RANGE"))
A16: J3 elbow | B16: =IF($B$11<>"REACHABLE (geometry only)","",DEGREES(B35)) | C16: =IF($B$11<>"REACHABLE (geometry only)","",Inputs!B14+Inputs!B29*B16) | D16: =IF($B$11<>"REACHABLE (geometry only)","",IF(AND(C16>=Inputs!$B$37,C16<=Inputs!$C$37),"OK","OUT OF RANGE"))
A17: J4 wrist roll (fixed at reference) | B17: 0 | C17: =IF($B$11<>"REACHABLE (geometry only)","",Inputs!B15+Inputs!B30*B17) | D17: =IF($B$11<>"REACHABLE (geometry only)","",IF(AND(C17>=Inputs!$B$38,C17<=Inputs!$C$38),"OK","OUT OF RANGE"))
A18: J5 wrist pitch | B18: =IF($B$11<>"REACHABLE (geometry only)","",DEGREES(B36)) | C18: =IF($B$11<>"REACHABLE (geometry only)","",Inputs!B16+Inputs!B31*B18) | D18: =IF($B$11<>"REACHABLE (geometry only)","",IF(AND(C18>=Inputs!$B$39,C18<=Inputs!$C$39),"OK","OUT OF RANGE"))
A21: Calculation steps
A22: φ (rad) | B22: =RADIANS(B8)
A23: o_x = tool offset along arm-plane X after pitch | B23: =Model_Params!B11*COS(B22)+Model_Params!D11*SIN(B22)
A24: o_z = tool offset along Z after pitch | B24: =-Model_Params!B11*SIN(B22)+Model_Params!D11*COS(B22)
A25: y_t = TCP sideways offset in the arm plane (mm) | B25: =Model_Params!C5+Model_Params!C11
A26: r = horizontal distance of target from J1 axis (mm) | B26: =SQRT(B5^2+B6^2)
A27: x' = in-plane radial coordinate of the target (mm) | B27: =IF(B26<ABS(B25),0,SQRT(B26^2-B25^2))
A28: Δx = wrist-centre x − shoulder x (mm) | B28: =B27-B23-Model_Params!B5
A29: Δz = wrist-centre z − shoulder z (mm) | B29: =B7-B24-Model_Params!D5
A30: D = cos(elbow angle) | B30: =(B28^2+B29^2-Model_Params!B14^2-Model_Params!B15^2)/(2*Model_Params!B14*Model_Params!B15)
A31: γ = elbow angle between links (rad) | B31: =IF($B$11<>"REACHABLE (geometry only)","",B9*ACOS(B30))
A32: θ1 = upper-arm angle from vertical (rad) | B32: =ATAN2(B29,B28)-ATAN2(Model_Params!B14+Model_Params!B15*COS(B31),Model_Params!B15*SIN(B31))
A33: q1 (rad) | B33: =ATAN2(B5,B6)-ATAN2(B27,B25)
A34: q2 (rad) | B34: =B32-Model_Params!B16
A35: q3 (rad) | B35: =B31+Model_Params!B16
A36: q5 (rad) | B36: =B22-B34-B35
A37: q4 (rad) – fixed | B37: =0
A39: Round-trip check: run the IK result back through forward kinematics
A41: u = Ry(q5)·t | B41: =Model_Params!$B$11*COS($B$36)+Model_Params!$D$11*SIN($B$36) | C41: =Model_Params!$C$11 | D41: =-Model_Params!$B$11*SIN($B$36)+Model_Params!$D$11*COS($B$36)
A42: v = Rz(q4)·u | B42: =COS($B$37)*B41-SIN($B$37)*C41 | C42: =SIN($B$37)*B41+COS($B$37)*C41 | D42: =D41
A43: w = v_EW + v | B43: =Model_Params!$B$10+B42 | C43: =Model_Params!$C$10+C42 | D43: =Model_Params!$D$10+D42
A44: q2+q3 (rad) | B44: =$B$34+$B$35
A45: Ry(q2+q3)·w | B45: =B43*COS(B44)+D43*SIN(B44) | C45: =C43 | D45: =-B43*SIN(B44)+D43*COS(B44)
A46: Ry(q2)·v_SE | B46: =Model_Params!$B$9*COS($B$34)+Model_Params!$D$9*SIN($B$34) | C46: =Model_Params!$C$9 | D46: =-Model_Params!$B$9*SIN($B$34)+Model_Params!$D$9*COS($B$34)
...

Sheet Test_Vectors
A1: Test vectors from the Fusion model (ground truth for your code)
A2: Each CAD value was obtained by posing the Fusion joints, reading the moved tool point, and restoring the joints. Model angles q follow the + definitions on Servo_Map (Fusion joint value = [−q1, −q2, +q3, −q4, −q5]). Tool point = Inputs TCP (10.15, 9.52, 438.5 at zero). Columns J–L are this workbook's FK; M is the largest difference. These are typed CAD readings, not hardware measurements. Rounding q to 0.01° can produce ≈0.028 mm in this model alone; any remaining CAD-vs-model difference is not explained here.
P3: helper columns (FK steps, same equations as FK_Calculator)
A4: Case | B4: q1 (deg) | C4: q2 | D4: q3 | E4: q4 | F4: q5 | G4: CAD X (mm) | H4: CAD Y | I4: CAD Z | J4: Sheet FK X | K4: Sheet FK Y | L4: Sheet FK Z | M4: Max |diff| (mm) | P4: q1 rad | Q4: q2 rad | R4: q3 rad | S4: q4 rad | T4: q5 rad | U4: u x | V4: u y | W4: u z | X4: v x | Y4: v y | Z4: v z | AA4: w x | AB4: w y | AC4: w z | AD4: q2+q3 | AE4: p' x | AF4: p' y | AG4: p' z
A5: Zero / reference pose | B5: 0 | C5: 0 | D5: 0 | E5: 0 | F5: 0 | G5: 10.15 | H5: 9.52 | I5: 438.5 | J5: =COS(P5)*AE5-SIN(P5)*AF5 | K5: =SIN(P5)*AE5+COS(P5)*AF5 | L5: =AG5 | M5: =MAX(ABS(J5-G5),ABS(K5-H5),ABS(L5-I5)) | P5: =RADIANS(B5) | Q5: =RADIANS(C5) | R5: =RADIANS(D5) | S5: =RADIANS(E5) | T5: =RADIANS(F5) | U5: =Model_Params!$B$11*COS(T5)+Model_Params!$D$11*SIN(T5) | V5: =Model_Params!$C$11 | W5: =-Model_Params!$B$11*SIN(T5)+Model_Params!$D$11*COS(T5) | X5: =COS(S5)*U5-SIN(S5)*V5 | Y5: =SIN(S5)*U5+COS(S5)*V5 | Z5: =W5 | AA5: =Model_Params!$B$10+X5 | AB5: =Model_Params!$C$10+Y5 | AC5: =Model_Params!$D$10+Z5 | AD5: =Q5+R5 | AE5: =AA5*COS(AD5)+AC5*SIN(AD5)+(Model_Params!$B$9*COS(Q5)+Model_Params!$D$9*SIN(Q5))+Model_Params!$B$5 | AF5: =AB5+Model_Params!$C$9+Model_Params!$C$5 | AG5: =-AA5*SIN(AD5)+AC5*COS(AD5)+(-Model_Params!$B$9*SIN(Q5)+Model_Params!$D$9*COS(Q5))+Model_Params!$D$5
A6: J1 only: q1 = −30 | B6: -30 | C6: 0 | D6: 0 | E6: 0 | F6: 0 | G6: 13.55 | H6: 3.17 | I6: 438.5 | J6: =COS(P6)*AE6-SIN(P6)*AF6 | K6: =SIN(P6)*AE6+COS(P6)*AF6 | L6: =AG6 | M6: =MAX(ABS(J6-G6),ABS(K6-H6),ABS(L6-I6)) | P6: =RADIANS(B6) | Q6: =RADIANS(C6) | R6: =RADIANS(D6) | S6: =RADIANS(E6) | T6: =RADIANS(F6) | U6: =Model_Params!$B$11*COS(T6)+Model_Params!$D$11*SIN(T6) | V6: =Model_Params!$C$11 | W6: =-Model_Params!$B$11*SIN(T6)+Model_Params!$D$11*COS(T6) | X6: =COS(S6)*U6-SIN(S6)*V6 | Y6: =SIN(S6)*U6+COS(S6)*V6 | Z6: =W6 | AA6: =Model_Params!$B$10+X6 | AB6: =Model_Params!$C$10+Y6 | AC6: =Model_Params!$D$10+Z6 | AD6: =Q6+R6 | AE6: =AA6*COS(AD6)+AC6*SIN(AD6)+(Model_Params!$B$9*COS(Q6)+Model_Params!$D$9*SIN(Q6))+Model_Params!$B$5 | AF6: =AB6+Model_Params!$C$9+Model_Params!$C$5 | AG6: =-AA6*SIN(AD6)+AC6*COS(AD6)+(-Model_Params!$B$9*SIN(Q6)+Model_Params!$D$9*COS(Q6))+Model_Params!$D$5
A7: J2 only: q2 = −30 | B7: 0 | C7: -30 | D7: 0 | E7: 0 | F7: 0 | G7: -160.25 | H7: 9.52 | I7: 385.88 | J7: =COS(P7)*AE7-SIN(P7)*AF7 | K7: =SIN(P7)*AE7+COS(P7)*AF7 | L7: =AG7 | M7: =MAX(ABS(J7-G7),ABS(K7-H7),ABS(L7-I7)) | P7: =RADIANS(B7) | Q7: =RADIANS(C7) | R7: =RADIANS(D7) | S7: =RADIANS(E7) | T7: =RADIANS(F7) | U7: =Model_Params!$B$11*COS(T7)+Model_Params!$D$11*SIN(T7) | V7: =Model_Params!$C$11 | W7: =-Model_Params!$B$11*SIN(T7)+Model_Params!$D$11*COS(T7) | X7: =COS(S7)*U7-SIN(S7)*V7 | Y7: =SIN(S7)*U7+COS(S7)*V7 | Z7: =W7 | AA7: =Model_Params!$B$10+X7 | AB7: =Model_Params!$C$10+Y7 | AC7: =Model_Params!$D$10+Z7 | AD7: =Q7+R7 | AE7: =AA7*COS(AD7)+AC7*SIN(AD7)+(Model_Params!$B$9*COS(Q7)+Model_Params!$D$9*SIN(Q7))+Model_Params!$B$5 | AF7: =AB7+Model_Params!$C$9+Model_Params!$C$5 | AG7: =-AA7*SIN(AD7)+AC7*COS(AD7)+(-Model_Params!$B$9*SIN(Q7)+Model_Params!$D$9*COS(Q7))+Model_Params!$D$5
A8: J3 only: q3 = +30 | B8: 0 | C8: 0 | D8: 30 | E8: 0 | F8: 0 | G8: 127.47 | H8: 9.53 | I8: 414.03 | J8: =COS(P8)*AE8-SIN(P8)*AF8 | K8: =SIN(P8)*AE8+COS(P8)*AF8 | L8: =AG8 | M8: =MAX(ABS(J8-G8),ABS(K8-H8),ABS(L8-I8)) | P8: =RADIANS(B8) | Q8: =RADIANS(C8) | R8: =RADIANS(D8) | S8: =RADIANS(E8) | T8: =RADIANS(F8) | U8: =Model_Params!$B$11*COS(T8)+Model_Params!$D$11*SIN(T8) | V8: =Model_Params!$C$11 | W8: =-Model_Params!$B$11*SIN(T8)+Model_Params!$D$11*COS(T8) | X8: =COS(S8)*U8-SIN(S8)*V8 | Y8: =SIN(S8)*U8+COS(S8)*V8 | Z8: =W8 | AA8: =Model_Params!$B$10+X8 | AB8: =Model_Params!$C$10+Y8 | AC8: =Model_Params!$D$10+Z8 | AD8: =Q8+R8 | AE8: =AA8*COS(AD8)+AC8*SIN(AD8)+(Model_Params!$B$9*COS(Q8)+Model_Params!$D$9*SIN(Q8))+Model_Params!$B$5 | AF8: =AB8+Model_Params!$C$9+Model_Params!$C$5 | AG8: =-AA8*SIN(AD8)+AC8*COS(AD8)+(-Model_Params!$B$9*SIN(Q8)+Model_Params!$D$9*COS(Q8))+Model_Params!$D$5
A9: J4 only: q4 = −30 | B9: 0 | C9: 0 | D9: 0 | E9: -30 | F9: 0 | G9: 9.03 | H9: 16.78 | I9: 438.5 | J9: =COS(P9)*AE9-SIN(P9)*AF9 | K9: =SIN(P9)*AE9+COS(P9)*AF9 | L9: =AG9 | M9: =MAX(ABS(J9-G9),ABS(K9-H9),ABS(L9-I9)) | P9: =RADIANS(B9) | Q9: =RADIANS(C9) | R9: =RADIANS(D9) | S9: =RADIANS(E9) | T9: =RADIANS(F9) | U9: =Model_Params!$B$11*COS(T9)+Model_Params!$D$11*SIN(T9) | V9: =Model_Params!$C$11 | W9: =-Model_Params!$B$11*SIN(T9)+Model_Params!$D$11*COS(T9) | X9: =COS(S9)*U9-SIN(S9)*V9 | Y9: =SIN(S9)*U9+COS(S9)*V9 | Z9: =W9 | AA9: =Model_Params!$B$10+X9 | AB9: =Model_Params!$C$10+Y9 | AC9: =Model_Params!$D$10+Z9 | AD9: =Q9+R9 | AE9: =AA9*COS(AD9)+AC9*SIN(AD9)+(Model_Params!$B$9*COS(Q9)+Model_Params!$D$9*SIN(Q9))+Model_Params!$B$5 | AF9: =AB9+Model_Params!$C$9+Model_Params!$C$5 | AG9: =-AA9*SIN(AD9)+AC9*COS(AD9)+(-Model_Params!$B$9*SIN(Q9)+Model_Params!$D$9*COS(Q9))+Model_Params!$D$5
A10: J5 only: q5 = −30 | B10: 0 | C10: 0 | D10: 0 | E10: 0 | F10: -30 | G10: -40.49 | H10: 9.52 | I10: 417.97 | J10: =COS(P10)*AE10-SIN(P10)*AF10 | K10: =SIN(P10)*AE10+COS(P10)*AF10 | L10: =AG10 | M10: =MAX(ABS(J10-G10),ABS(K10-H10),ABS(L10-I10)) | P10: =RADIANS(B10) | Q10: =RADIANS(C10) | R10: =RADIANS(D10) | S10: =RADIANS(E10) | T10: =RADIANS(F10) | U10: =Model_Params!$B$11*COS(T10)+Model_Params!$D$11*SIN(T10) | V10: =Model_Params!$C$11 | W10: =-Model_Params!$B$11*SIN(T10)+Model_Params!$D$11*COS(T10) | X10: =COS(S10)*U10-SIN(S10)*V10 | Y10: =SIN(S10)*U10+COS(S10)*V10 | Z10: =W10 | AA10: =Model_Params!$B$10+X10 | AB10: =Model_Params!$C$10+Y10 | AC10: =Model_Params!$D$10+Z10 | AD10: =Q10+R10 | AE10: =AA10*COS(AD10)+AC10*SIN(AD10)+(Model_Params!$B$9*COS(Q10)+Model_Params!$D$9*SIN(Q10))+Model_Params!$B$5 | AF10: =AB10+Model_Params!$C$9+Model_Params!$C$5 | AG10: =-AA10*SIN(AD10)+AC10*COS(AD10)+(-Model_Params!$B$9*SIN(Q10)+Model_Params!$D$9*COS(Q10))+Model_Params!$D$5
A11: Combined 1 | B11: 20 | C11: 25 | D11: -40 | E11: 35 | F11: 30 | G11: 34.17 | H11: 48.76 | I11: 422.31 | J11: =COS(P11)*AE11-SIN(P11)*AF11 | K11: =SIN(P11)*AE11+COS(P11)*AF11 | L11: =AG11 | M11: =MAX(ABS(J11-G11),ABS(K11-H11),ABS(L11-I11)) | P11: =RADIANS(B11) | Q11: =RADIANS(C11) | R11: =RADIANS(D11) | S11: =RADIANS(E11) | T11: =RADIANS(F11) | U11: =Model_Params!$B$11*COS(T11)+Model_Params!$D$11*SIN(T11) | V11: =Model_Params!$C$11 | W11: =-Model_Params!$B$11*SIN(T11)+Model_Params!$D$11*COS(T11) | X11: =COS(S11)*U11-SIN(S11)*V11 | Y11: =SIN(S11)*U11+COS(S11)*V11 | Z11: =W11 | AA11: =Model_Params!$B$10+X11 | AB11: =Model_Params!$C$10+Y11 | AC11: =Model_Params!$D$10+Z11 | AD11: =Q11+R11 | AE11: =AA11*COS(AD11)+AC11*SIN(AD11)+(Model_Params!$B$9*COS(Q11)+Model_Params!$D$9*SIN(Q11))+Model_Params!$B$5 | AF11: =AB11+Model_Params!$C$9+Model_Params!$C$5 | AG11: =-AA11*SIN(AD11)+AC11*COS(AD11)+(-Model_Params!$B$9*SIN(Q11)+Model_Params!$D$9*COS(Q11))+Model_Params!$D$5
A12: Combined 2 | B12: -50 | C12: 60 | D12: 45 | E12: -70 | F12: -25 | G12: 266.49 | H12: -214.96 | I12: 118.63 | J12: =COS(P12)*AE12-SIN(P12)*AF12 | K12: =SIN(P12)*AE12+COS(P12)*AF12 | L12: =AG12 | M12: =MAX(ABS(J12-G12),ABS(K12-H12),ABS(L12-I12)) | P12: =RADIANS(B12) | Q12: =RADIANS(C12) | R12: =RADIANS(D12) | S12: =RADIANS(E12) | T12: =RADIANS(F12) | U12: =Model_Params!$B$11*COS(T12)+Model_Params!$D$11*SIN(T12) | V12: =Model_Params!$C$11 | W12: =-Model_Params!$B$11*SIN(T12)+Model_Params!$D$11*COS(T12) | X12: =COS(S12)*U12-SIN(S12)*V12 | Y12: =SIN(S12)*U12+COS(S12)*V12 | Z12: =W12 | AA12: =Model_Params!$B$10+X12 | AB12: =Model_Params!$C$10+Y12 | AC12: =Model_Params!$D$10+Z12 | AD12: =Q12+R12 | AE12: =AA12*COS(AD12)+AC12*SIN(AD12)+(Model_Params!$B$9*COS(Q12)+Model_Params!$D$9*SIN(Q12))+Model_Params!$B$5 | AF12: =AB12+Model_Params!$C$9+Model_Params!$C$5 | AG12: =-AA12*SIN(AD12)+AC12*COS(AD12)+(-Model_Params!$B$9*SIN(Q12)+Model_Params!$D$9*COS(Q12))+Model_Params!$D$5
A13: Combined 3 | B13: 110 | C13: -15 | D13: 80 | E13: 150 | F13: 95 | G13: -94.04 | H13: 45.03 | I13: 338.71 | J13: =COS(P13)*AE13-SIN(P13)*AF13 | K13: =SIN(P13)*AE13+COS(P13)*AF13 | L13: =AG13 | M13: =MAX(ABS(J13-G13),ABS(K13-H13),ABS(L13-I13)) | P13: =RADIANS(B13) | Q13: =RADIANS(C13) | R13: =RADIANS(D13) | S13: =RADIANS(E13) | T13: =RADIANS(F13) | U13: =Model_Params!$B$11*COS(T13)+Model_Params!$D$11*SIN(T13) | V13: =Model_Params!$C$11 | W13: =-Model_Params!$B$11*SIN(T13)+Model_Params!$D$11*COS(T13) | X13: =COS(S13)*U13-SIN(S13)*V13 | Y13: =SIN(S13)*U13+COS(S13)*V13 | Z13: =W13 | AA13: =Model_Params!$B$10+X13 | AB13: =Model_Params!$C$10+Y13 | AC13: =Model_Params!$D$10+Z13 | AD13: =Q13+R13 | AE13: =AA13*COS(AD13)+AC13*SIN(AD13)+(Model_Params!$B$9*COS(Q13)+Model_Params!$D$9*SIN(Q13))+Model_Params!$B$5 | AF13: =AB13+Model_Params!$C$9+Model_Params!$C$5 | AG13: =-AA13*SIN(AD13)+AC13*COS(AD13)+(-Model_Params!$B$9*SIN(Q13)+Model_Params!$D$9*COS(Q13))+Model_Params!$D$5
A15: Worst difference over all 9 typed-CAD FK cases (mm) | M15: =MAX(M5:M13)
A17: IK cases checked in the CAD (poses set from the IK output, angles rounded to 0.01°, then the CAD tool point read back; typed CAD, not hardware proof)
A18: Case | B18: Target X | C18: Target Y | D18: Target Z | E18: φ (deg) | F18: Elbow branch | G18: q1 (deg) | H18: q2 | I18: q3 | J18: q5 (q4 = 0) | K18: CAD tool X | L18: CAD tool Y | M18: CAD tool Z | N18: Max error (mm)
A19: IK 1 (branch +1) | B19: 180 | C19: 30 | D19: 100 | E19: 180 | F19: 1 | G19: 6.47 | H19: 10.03 | I19: 80.35 | J19: 89.61 | K19: 179.92 | L19: 30.08 | M19: 99.98 | N19: =MAX(ABS(K19-B19),ABS(L19-C19),ABS(M19-D19))
A20: IK 2 (branch −1) | B20: 180 | C20: 30 | D20: 100 | E20: 180 | F20: -1 | G20: 6.47 | H20: 95.75 | I20: -80.36 | J20: 164.61 | K20: 179.99 | L20: 30.09 | M20: 99.9 | N20: =MAX(ABS(K20-B20),ABS(L20-C20),ABS(M20-D20))
A21: IK 3 | B21: 150 | C21: -40 | D21: 200 | E21: 120 | F21: 1 | G21: -18.45 | H21: -41.72 | I21: 102.1 | J21: 59.63 | K21: 150.03 | L21: -40.15 | M21: 199.98 | N21: =MAX(ABS(K21-B21),ABS(L21-C21),ABS(M21-D21))
A22: IK 4 | B22: 100 | C22: 0 | D22: 300 | E22: 90 | F22: 1 | G22: -5.46 | H22: -46.26 | I22: 71.23 | J22: 65.03 | K22: 99.77 | L22: -0.04 | M22: 300.19 | N22: =MAX(ABS(K22-B22),ABS(L22-C22),ABS(M22-D22))
A24: Enter any IK row's target, φ and branch into IK_Calculator to reproduce its q values. The 4 typed-CAD IK errors peak at 0.23 mm, but rounding angles to 0.01° contributes only ≈0.028 mm in this model; the rest of the CAD-vs-model difference is unexplained here. This is not hardware proof.

Sheet J1_Location
A1: J1 rotation axis on the base plate
A2: J1 = CAD joint 'Revolute Base' (base_link_upper ↔ base_link). Axis is vertical. Concentric features: MG996R base servo spline (r 3.0/5.4/6.6), bearing 02300254 bore r 15.0, base_link bores r 11.0 & 14.95, base horn.
A4: Plate edge (Fusion) | B4: Edge coordinate (mm) | C4: Coordinate axis | D4: Straight length (mm) | E4: Perpendicular offset edge → J1 axis (mm) | F4: Use on real plate | G4: Note
A5: Short edge, Fusion −X side | B5: -85 | C5: X | D5: 108 | E5: =ABS(Inputs!$B$7-B5) | F5: Yes – recommended | G5: Measure ≥10 mm from R10 corners
A6: Short edge, Fusion +X side | B6: 101.5 | C6: X | D6: 108 | E6: =ABS(Inputs!$B$7-B6) | F6: Check
A7: Long edge, Fusion −Z side | B7: -46 | C7: Z | D7: 166.5 | E7: =ABS(Inputs!$B$8-B7) | F7: Yes – recommended | G7: Console spacer pad is beyond this edge (Fusion Z −95…−65)
A8: Long edge, Fusion +Z side | B8: 82 | C8: Z | D8: 166.5 | E8: =ABS(Inputs!$B$8-B8) | F8: Check
A10: Checks
A11: Plate length along Fusion X (sum of short-edge offsets) | E11: =E5+E6 | G11: Should be 186.5 on the real plate
A12: Plate width along Fusion Z (sum of long-edge offsets) | E12: =E7+E8 | G12: Should be 128.0 on the real plate
A13: Plate centre Fusion X | E13: =(B5+B6)/2
A14: Plate centre Fusion Z | E14: =(B7+B8)/2
A15: J1 offset from plate centre along Fusion X | E15: =Inputs!$B$7-(B5+B6)/2 | G15: J1 is NOT at plate centre
A16: J1 offset from plate centre along Fusion Z | E16: =Inputs!$B$8-(B7+B8)/2
A17: Distance J1 axis → screw hole at (−54, 18.2), centre-to-centre | E17: =SQRT((Inputs!$B$7-(-54))^2+(Inputs!$B$8-18.2)^2) | G17: Extra cross-check on the real plate (hole Ø2.6)
A18: Plate thickness | E18: =Inputs!B10-Inputs!B9 | G18: CAD: no feet; bottom face is lowest geometry
A20: Other base-plate features (Fusion coords, mm)
A21: Feature | B21: Fusion X | C21: Fusion Z | D21: Radius (mm) | E21: Distance to J1 axis (mm)
A22: Screw hole | B22: 60 | C22: 71.6 | D22: 1.3 | E22: =SQRT((B22-Inputs!$B$7)^2+(C22-Inputs!$B$8)^2)
A23: Screw hole | B23: 60 | C23: -35.6 | D23: 1.3 | E23: =SQRT((B23-Inputs!$B$7)^2+(C23-Inputs!$B$8)^2)
A24: Screw hole (in line with J1) | B24: -54 | C24: 18.2 | D24: 1.3 | E24: =SQRT((B24-Inputs!$B$7)^2+(C24-Inputs!$B$8)^2)
A25: Opening corner arc centre | B25: 72 | C25: -22 | D25: 6 | E25: =SQRT((B25-Inputs!$B$7)^2+(C25-Inputs!$B$8)^2)
A26: Opening corner arc centre | B26: 72 | C26: 58 | D26: 6 | E26: =SQRT((B26-Inputs!$B$7)^2+(C26-Inputs!$B$8)^2)
A27: Opening corner arc centre | B27: -38 | C27: -22 | D27: 6 | E27: =SQRT((B27-Inputs!$B$7)^2+(C27-Inputs!$B$8)^2)
A28: Opening corner arc centre | B28: -38 | C28: 58 | D28: 6 | E28: =SQRT((B28-Inputs!$B$7)^2+(C28-Inputs!$B$8)^2)
A30: Through-opening under base: 122 × 92 mm, edges at Fusion X −44 / +78 and Z −28 / +64 (R6 corners). Inner-edge offsets to J1: 44.00 / 78.00 / 46.18 / 45.82 mm – likely hidden under the base on the real arm.
A33: Transfer procedure (real plate)
A34: 1. Pick one short edge and one long edge (recommended rows marked above). Measure on straight parts, ≥10 mm from the R10 corners.
A35: 2. From the short edge, measure the offset in column E perpendicular inward and mark that point. Through the point, draw a line parallel to that edge.
A36: 3. From the long edge, measure its offset perpendicular inward and mark it; draw a second line parallel to the long edge. The intersection = J1 axis.
A37: 4. Cross-check: intersection should be 54.0 mm from the centre of the screw hole in line with J1, and both pairs of opposite-edge offsets should sum to the plate size (Checks above). If not, the real plate differs from CAD – measure the real plate.
A38: 5. Floor origin = that point projected down to the support plane. Add foot height (Inputs!B6) if the plate stands on feet/pads.

Sheet Joint_Axes
A1: Revolute joint axes from CAD (as-built pose, all arm joints at Fusion 0°)
A2: Each joint gives ONE point on its axis + the axis direction. The coordinate ALONG the axis is arbitrary (e.g. Robot Y of a horizontal axis, Robot Z of a vertical axis) – use only the perpendicular components.
A4: Joint (ours) | B4: CAD joint name | C4: Moving part | D4: Fixed part | E4: Fusion rot now (deg) | F4: Fusion X | G4: Fusion Y | H4: Fusion Z | I4: Axis dX | J4: Axis dY | K4: Axis dZ | L4: Robot X (mm) | M4: Robot Y (mm) | N4: Robot Z above floor (mm) | O4: Robot axis X | P4: Robot axis Y | Q4: Robot axis Z | R4: Arbitrary component
A5: J1 base yaw | B5: Revolute Base | C5: base_link_upper:1 | D5: base_link:1 | E5: 0 | F5: 0 | G5: 20 | H5: 18.18 | I5: 0 | J5: -1 | K5: 0 | L5: =IF(Inputs!$B$5="","set arrow",Inputs!$B$5*(F5-Inputs!$B$7)) | M5: =IF(Inputs!$B$5="","set arrow",-Inputs!$B$5*(H5-Inputs!$B$8)) | N5: =G5-Inputs!$B$9+Inputs!$B$6 | O5: =IF(Inputs!$B$5="","set arrow",Inputs!$B$5*I5+0) | P5: =IF(Inputs!$B$5="","set arrow",-Inputs!$B$5*K5+0) | Q5: =J5+0 | R5: Robot Z
A6: J2 shoulder | B6: Revolute Shoulder | C6: arm_link_1:1 | D6: base_link_upper:1 | E6: 0 | F6: -23.15 | G6: 59.72 | H6: 14.08 | I6: 0 | J6: 0 | K6: -1 | L6: =IF(Inputs!$B$5="","set arrow",Inputs!$B$5*(F6-Inputs!$B$7)) | M6: =IF(Inputs!$B$5="","set arrow",-Inputs!$B$5*(H6-Inputs!$B$8)) | N6: =G6-Inputs!$B$9+Inputs!$B$6 | O6: =IF(Inputs!$B$5="","set arrow",Inputs!$B$5*I6+0) | P6: =IF(Inputs!$B$5="","set arrow",-Inputs!$B$5*K6+0) | Q6: =J6+0 | R6: Robot Y
A7: J3 elbow | B7: Revolute Elbow | C7: arm_link_2:1 | D7: arm_link_1:1 | E7: 0 | F7: -23.14 | G7: 172.84 | H7: 21.18 | I7: 0 | J7: 0 | K7: 1 | L7: =IF(Inputs!$B$5="","set arrow",Inputs!$B$5*(F7-Inputs!$B$7)) | M7: =IF(Inputs!$B$5="","set arrow",-Inputs!$B$5*(H7-Inputs!$B$8)) | N7: =G7-Inputs!$B$9+Inputs!$B$6 | O7: =IF(Inputs!$B$5="","set arrow",Inputs!$B$5*I7+0) | P7: =IF(Inputs!$B$5="","set arrow",-Inputs!$B$5*K7+0) | Q7: =J7+0 | R7: Robot Y
A8: J4 wrist roll | B8: Revolute Wrist Roll | C8: arm_link_3:1 | D8: arm_link_2:1 | E8: 0 | F8: -23.14 | G8: 273.99 | H8: 33.43 | I8: 0 | J8: -1 | K8: 0 | L8: =IF(Inputs!$B$5="","set arrow",Inputs!$B$5*(F8-Inputs!$B$7)) | M8: =IF(Inputs!$B$5="","set arrow",-Inputs!$B$5*(H8-Inputs!$B$8)) | N8: =G8-Inputs!$B$9+Inputs!$B$6 | O8: =IF(Inputs!$B$5="","set arrow",Inputs!$B$5*I8+0) | P8: =IF(Inputs!$B$5="","set arrow",-Inputs!$B$5*K8+0) | Q8: =J8+0 | R8: Robot Z
A9: J5 wrist pitch | B9: Revolute Wrist Pitch | C9: gripper_base:1 | D9: arm_link_3:1 | E9: 0 | F9: -23.14 | G9: 299.24 | H9: 13.18 | I9: 0 | J9: 0 | K9: -1 | L9: =IF(Inputs!$B$5="","set arrow",Inputs!$B$5*(F9-Inputs!$B$7)) | M9: =IF(Inputs!$B$5="","set arrow",-Inputs!$B$5*(H9-Inputs!$B$8)) | N9: =G9-Inputs!$B$9+Inputs!$B$6 | O9: =IF(Inputs!$B$5="","set arrow",Inputs!$B$5*I9+0) | P9: =IF(Inputs!$B$5="","set arrow",-Inputs!$B$5*K9+0) | Q9: =J9+0 | R9: Robot Y
A10: J6 gripper gear L | B10: Revolute Gripper Gear Left | C10: gripper_gear_left:1 | D10: gripper_base:1 | E10: 20 | F10: -7.14 | G10: 324.32 | H10: 43.65 | I10: 1 | J10: 0 | K10: 0 | L10: =IF(Inputs!$B$5="","set arrow",Inputs!$B$5*(F10-Inputs!$B$7)) | M10: =IF(Inputs!$B$5="","set arrow",-Inputs!$B$5*(H10-Inputs!$B$8)) | N10: =G10-Inputs!$B$9+Inputs!$B$6 | O10: =IF(Inputs!$B$5="","set arrow",Inputs!$B$5*I10+0) | P10: =IF(Inputs!$B$5="","set arrow",-Inputs!$B$5*K10+0) | Q10: =J10+0 | R10: Robot X
A11: J6 gripper gear R | B11: Revolute Gripper Gear Right | C11: gripper_gear_right:1 | D11: gripper_base:1 | E11: 20 | F11: -7.14 | G11: 324.32 | H11: 15.89 | I11: -1 | J11: 0 | K11: 0 | L11: =IF(Inputs!$B$5="","set arrow",Inputs!$B$5*(F11-Inputs!$B$7)) | M11: =IF(Inputs!$B$5="","set arrow",-Inputs!$B$5*(H11-Inputs!$B$8)) | N11: =G11-Inputs!$B$9+Inputs!$B$6 | O11: =IF(Inputs!$B$5="","set arrow",Inputs!$B$5*I11+0) | P11: =IF(Inputs!$B$5="","set arrow",-Inputs!$B$5*K11+0) | Q11: =J11+0 | R11: Robot X
A13: Note: J6 gear axes are the gripper drive gears (gripper servo SG92R:2). Fusion shows them at 20° in the as-built pose. No TCP / jaw-tip frame is defined in the CAD; gripper jaw parts reach Fusion Y ≈ 409.1 (bounding box only).

Sheet Link_Lengths
A1: Distances between axes (for FK / IK)
A2: All computed from Joint_Axes. Distances between parallel axes do not depend on pose; that is a local link-length qualification, not a statement about global coordinates. Vertical spacings assume the CAD as-built pose (arm straight up). J3→J5 is the parallel-axis reference, not the full roll geometry.
A4: Quantity | B4: Value (mm) | C4: Pose-independent? | D4: How it is computed / note
A5: J2 shoulder axis height above floor | B5: =Joint_Axes!G6-Inputs!$B$9+Inputs!$B$6 | C5: No (fixed by base/foot height; independent of arm joint angles) | D5: Fusion Y of shoulder − plate bottom + foot height
A6: J2 axis horizontal offset from J1 axis (along arm plane / robot X at J1=0) | B6: =ABS(Joint_Axes!F6-Joint_Axes!F5) | C6: Yes (local offset with the current frame mapping) | D6: |ΔFusion X| between shoulder and base axes
A7: J2 → J3 (shoulder → elbow) link length | B7: =SQRT((Joint_Axes!F7-Joint_Axes!F6)^2+(Joint_Axes!G7-Joint_Axes!G6)^2) | C7: Yes (local link length) | D7: In-plane distance between the two parallel axes (local length, not a global coordinate).
A8: J3 → J5 (elbow → wrist pitch) link length | B8: =SQRT((Joint_Axes!F9-Joint_Axes!F7)^2+(Joint_Axes!G9-Joint_Axes!G7)^2) | C8: Yes (local link length; J3→J5 parallel-axis reference) | D8: In-plane distance between the two parallel axes (local length; not full J4 roll geometry).
A9: J3 → J4 roll-axis start (along roll axis) | B9: =Joint_Axes!G8-Joint_Axes!G7 | C9: No | D9: Joint origin point only; roll axis is collinear with the arm
A10: J4 roll axis offset from J1 axis (sideways; Fusion Z difference = robot Y only with the current frame mapping) | B10: =Joint_Axes!H8-Inputs!$B$8 | C10: Yes | D10: Arm plane is offset sideways from J1 – include as d/offset in DH. The robot-axis label is frame-specific; re-derive it if the arrow/frame changes.
A11: J4 roll axis offset from J2/J3 line (along arm plane) | B11: =Joint_Axes!F8-Joint_Axes!F7 | C11: Yes | D11: ≈0 → roll axis passes through elbow/pitch line
A12: J5 → J6 gear pivots (along arm) | B12: =Joint_Axes!G10-Joint_Axes!G9 | C12: No | D12: Gear pivots, NOT the TCP
A13: J5 → gripper jaw extent (bounding box, rough) | B13: =409.1-Joint_Axes!G9 | C13: No | D13: Bounding box of jaw parts – not a defined TCP. Measure TCP on the real gripper.
A14: Top of shoulder chain at CAD pose: J5 height above floor | B14: =Joint_Axes!G9-Inputs!$B$9+Inputs!$B$6 | C14: No | D14: CAD pose only
A16: 409.1 = max Fusion Y of gripper_part_left (bounding box, typed in from CAD).

Sheet Object_Check
A1: Held-object position – comparison (CAD and physical kept separate)
A2: The block (15 × 25 × 15 mm, jaws across the 25 mm width, 15 mm vertical) is NOT modelled in the CAD, so no seated block centre was measured. The CAD rows below describe the jaw geometry only. The physical rows further below are preliminary ruler/approx readings, not a model fit. The reference TCP is CAD-derived/imposed, not an independently measured CAD block centre. CAD agreement does not validate the real arm's X/Y position or full FK.
A4: Quantity | B4: X (mm) | C4: Y (mm) | D4: Z (mm) | E4: Type | F4: Source / note
A5: Offline hybrid model prediction (block centre) | B5: 10.15 | C5: 9.52 | D5: 438.5 | E5: Model | F5: Our offline measured/CAD model (CAD-derived/imposed reference; not an independently measured CAD block centre)
A6: Physical: block top above floor | D6: 446 | E6: Physical | F6: Measured on the real arm
A7: Physical: derived block centre height | D7: =D6-15/2 | E7: Physical | F7: Level-top assumption, 15 mm vertical
A8: CAD jaw-gap centreline at the jaw tips (no block seated) | B8: 10.1 | C8: 9.37 | E8: CAD | F8: As-built pose, gripper gears at 20°. Jaw X extents −16.6…−3.6 (Fusion) → X = +10.10. Inner pad faces at Fusion Z 41.5 (left) and 13.6 (right): gap 27.9 mm, mid 27.55 → Y = +9.37.
A9: CAD jaw-pad top height (mean of left 439.5 and right 437.7) | D9: 438.6 | E9: CAD | F9: Height above the plate bottom. Same pose. Compare Z only if the plate sits flat on the floor.
A10: Difference: CAD jaw-gap − hybrid prediction | B10: =B8-B5 | C10: =C8-C5 | D10: =D9-D5 | F10: Small agreement only shows the offline model was built from this CAD geometry
A12: To do a true block-centre check, the 15 × 25 × 15 block must be added to the CAD and seated at the real grasp height/J6 holding angle (now known: 20°). Not done; the physical grip/TCP remains unmeasured.
A14: Physical measurements (preliminary, approximate; separate from the CAD rows above)
A15: Static repeats below: the block was not reseated and the joints were unchanged, so this is static measurement repeatability, not grip repeatability. The J1-only move and the return are separate approximate readings, not backlash or FK validation.
A17: Starting pose, J1 = 85° (other joints unchanged): static repeats, block not reseated
A18: Sample | B18: X (mm) | C18: Y (mm) | F18: Condition
A19: 1 | B19: 6 | C19: 7 | F19: Block not reseated; joints unchanged
A20: 2 | B20: 7.5 | C20: 10 | F20: Block not reseated; joints unchanged
A21: 3 | B21: 7 | C21: 9 | F21: Block not reseated; joints unchanged
A22: Mean | B22: =AVERAGE(B19:B21) | C22: =AVERAGE(C19:C21) | F22: Mean of the three static repeats; not a grip study.
A23: Min | B23: =MIN(B19:B21) | C23: =MIN(C19:C21) | F23: Range low.
A24: Max | B24: =MAX(B19:B21) | C24: =MAX(C19:C21) | F24: Range high: X 6.0–7.5 mm, Y 7.0–10.0 mm.
A25: Range width | B25: =B24-B23 | C25: =C24-C23 | F25: Max − min; measurement spread only.
A27: J1-only move: J1 = 100° (other joints unchanged; fixed coordinate frame, no slip)
A28: Quantity | B28: X (mm) | C28: Y low (mm) | D28: Y high (mm) | E28: Type | F28: Source / note
A29: Outward physical TCP (rough) | B29: 6 | C29: 8 | D29: 10 | E29: Physical | F29: Rough: X is one approximate reading and Y an 8–10 mm interval. Not repeated and not used as the reference.
A31: Return to J1 = 85° after the J1-only move
A32: Quantity | B32: X (mm) | C32: Y (mm) | D32: Z (mm) | E32: Type | F32: Source / note
A33: Return physical TCP (latest, approximate) | B33: 8 | C33: 7 | E33: Physical | F33: Latest approximate single reading; this is the return, not the starting reference.
A34: Return − starting mean | B34: =B33-B22 | C34: =C33-C22 | E34: Difference | F34: +1.166667 mm X, −1.666667 mm Y. Return X is 0.5 mm above the starting X max (7.5), so it is outside the starting X range; cannot claim the return is within both ranges.
A35: Physical block top above floor (previous) | D35: 446 | E35: Physical | F35: Previous measured top; not remeasured in this repeat check.
A36: Physical implied block-centre Z | D36: =D35-15/2 | E36: Derived | F36: Level-top assumption, 15 mm vertical; not an independent centre measurement.
A37: Model reference Z (Inputs) | D37: =Inputs!B24 | E37: Model | F37: Reference Z was constructed from the same 446 mm top/15 mm assumption; matching Z is by construction, not independent validation.
A38: Δ implied centre − model | D38: =D36-D37 | E38: Difference | F38: Recorded comparison only; no calibration/fitting.
A40: 15° base-yaw comparison (J1 85→100; Rz formula only, not an independent Z check)
A41: Quantity | B41: X (mm) | C41: Y (mm) | F41: Source / note
A42: Model reference TCP at start | B42: =Inputs!B22 | C42: =Inputs!B23 | F42: Model.
A43: Model reference after Rz(+15°) | B43: =COS(RADIANS(15))*B42-SIN(RADIANS(15))*C42 | C43: =SIN(RADIANS(15))*B42+COS(RADIANS(15))*C42 | F43: Workbook prediction (~7.340, 11.823 mm).
A44: Measured starting mean | B44: =B22 | C44: =C22 | F44: Static mean from repeats above.
A45: Measured mean after Rz(+15°) | B45: =COS(RADIANS(15))*B44-SIN(RADIANS(15))*C44 | C45: =SIN(RADIANS(15))*B44+COS(RADIANS(15))*C44 | F45: Formula rotation of the measured mean (~4.357, 10.140 mm); hypothetical, not a measured outward point.
A46: Model rotated − measured mean rotated | B46: =B43-B45 | C46: =C43-C45 | F46: Formula difference only.
A48: Rz rotates X/Y only; Z is carried through unchanged, so this table is not independent Z verification. The rough J1 = 100 reading and the return reading are separate approximate readings; neither is a fit, a backlash measurement or full FK validation.

Sheet Open_Items
A1: Status of open items
A3: # | B3: Item | C3: Status | D3: What is needed
A4: 1 | B4: Forward direction (arrow) | C4: RESOLVED | D4: You said front = curved side of base_link; CAD shows that side is Fusion −X. Robot X = −Fusion X, Y = +Fusion Z (right-handed, checked).
A5: 2 | B5: J4 = roll, J5 = pitch | C5: RESOLVED | D5: Confirmed by you and by the CAD joint axes.
A6: 3 | B6: Servo reference pose = CAD as-built pose (all q = 0) | C6: PROVISIONAL – candidate zero | D6: 85/145/88/88/96 is user-supplied. Zero alignment needs a multipose physical check; the height match is by construction, not validation.
A7: 4 | B7: Servo direction signs J1–J5 | C7: KNOWN CANDIDATE – retest at 1° | D7: Candidate signs +1/−1/+1/+1/−1 are entered. Recheck each with a small slow 1° physical move (not IK output); J5 is provisional at J4 = 88°.
A8: 5 | B8: Foot / pad height under the plate | C8: OPEN – 0 assumed | D8: Inputs!B6 = 0 assumed; foot/pad height is still unmeasured.
A9: 6 | B9: J6 angle while holding the block | C9: KNOWN – 20° | D9: Inputs!B19 = 20° measured holding angle. 40° is startup/home only. The CAD block is still not seated and the physical grip/TCP remains unmeasured, so the holding pose is not CAD/FK-verified.
A10: 7 | B10: Real plate dimensions vs CAD (186.5 × 128 mm) | C10: OPEN | D10: Tape-measure; if different, measure J1 offsets on the real plate instead (J1_Location).
A11: 8 | B11: Servo limits / joint ranges | C11: KNOWN CANDIDATE – not collision-certified | D11: Per-joint candidate endpoints are in Inputs!B35:C40 (J1 0–180, J2 50–180, J3 45–180, J4 0–180, J5 25–140, J6 0–60). Endpoint checks only. Firmware motion retains commanded-state and pending-endpoint interlocks; physical path clearance and real collisions still need verification, with no automated collision guarantee.
A12: 9 | B12: Block seated in the CAD | C12: NOT DONE | D12: Optional; CAD currently has a different cube (cube_25mm) on the tray. The physical grip/TCP is still unknown, so the seated block pose is unverified.
A13: 10 | B13: Full IK incl. roll q4 | C13: NOT PROVIDED | D13: IK_Calculator fixes q4 = 0. A roll-including IK can be added if needed.
